Workbook

Sheet Cover
A1: Meridian Growth Partners III, L.P.
A2: Capital Call, Distribution Waterfall & NAV Model
B4: Prepared as of | C4: Q2 2026 (2026-06-30)
B5: Fund size (committed capital) | C5: 50000000
B6: Limited partners | C6: 15
B7: Vintage / investment period | C7: Q1 2022 – Q4 2024 (12 quarters)
B8: Fund term modeled | C8: Q1 2022 – Q2 2026 (18 quarters)
B10: How this workbook is organized
B11: Assumptions | C11: Fund terms: fee rate, preferred return, carry split, catch-up
B12: Quarters | C12: The 18-quarter calendar used throughout the model
B13: LP Register | C13: 15 limited partners and their commitments
B14: Portfolio Companies | C14: 10 portfolio company investments (cost, invest date, sector)
B15: Portfolio Marks | C15: Quarterly fair value marks and exit/recap events, by company
B16: Mgmt Fee Schedule | C16: 2% of committed capital during the investment period, stepping down to 2% of invested cost thereafter
B17: Capital Call Schedule | C17: Fund-level quarterly capital calls (investment + fee)
B18: LP Capital Calls | C18: Each LP's pro-rata share of every capital call
B19: Distribution Waterfall | C19: Return of capital → 8% preferred return → GP catch-up → 80/20 carry split, run cumulatively by quarter
B20: NAV Rollforward | C20: Quarterly Beginning NAV → Ending NAV bridge
B21: LP Capital Accounts | C21: Each LP's quarterly capital account statement
B22: LP Statement (Select LP) | C22: A single formatted LP statement — pick any LP from the dropdown
... B24: Variance Reconciliation | C24: GP ledger vs. fund administrator records — 4 identified breaks
B26: Legend
B27: Blue text | C27: Hardcoded input
B28: Black text | C28: Formula
B29: Green text | C29: Link to another sheet
B30: Yellow fill | C30: Key assumption
B32: Synthetic fund for portfolio/demonstration purposes. All LPs, portfolio companies, valuations and cash flows are generated data — see README.md.

Sheet Assumptions
A1: Fund Assumptions
A2: Key economic terms — change these and the model recalculates
B4: Fund name | C4: Meridian Growth Partners III, L.P.
B5: Committed capital | C5: 50000000
B6: Number of LPs | C6: 15
B7: Investment period (quarters) | C7: 12
B8: Total quarters modeled | C8: 18
B9: Management fee rate (annual, % of committed capital during investment period) | C9: 0.02
B10: Management fee rate post-investment-period (annual, % of invested cost) | C10: 0.02
B11: Preferred return / hurdle rate (annual, compounded quarterly) | C11: 0.08
B12: GP catch-up (% of catch-up tier to GP) | C12: 1
B13: Carried interest rate (GP share of profit above hurdle) | C13: 0.2
B15: Waterfall structure
B16: 1. Return of Capital — 100% to LPs until cumulative capital contributed has been returned
B17: 2. Preferred Return — 100% to LPs until the compounding hurdle above is paid in full
B18: 3. GP Catch-up — 100% to GP until GP has received 20% of (preferred + catch-up) paid to date
B19: 4. Carried Interest Split — 80% LP / 20% GP on all remaining distributions

Sheet Quarters
A1: Quarterly Calendar
B3: Quarter Index | C3: Year | D3: Quarter | E3: Label | F3: Quarter End | G3: In Investment Period
B4: 1 | C4: 2022 | D4: 1 | E4: Q1 2022 | F4: 44651 | G4: =B4<=Assumptions!$C$7 -> TRUE
B5: 2 | C5: 2022 | D5: 2 | E5: Q2 2022 | F5: 44742 | G5: =B5<=Assumptions!$C$7 -> TRUE
B6: 3 | C6: 2022 | D6: 3 | E6: Q3 2022 | F6: 44834 | G6: =B6<=Assumptions!$C$7 -> TRUE
B7: 4 | C7: 2022 | D7: 4 | E7: Q4 2022 | F7: 44926 | G7: =B7<=Assumptions!$C$7 -> TRUE
B8: 5 | C8: 2023 | D8: 1 | E8: Q1 2023 | F8: 45016 | G8: =B8<=Assumptions!$C$7 -> TRUE
B9: 6 | C9: 2023 | D9: 2 | E9: Q2 2023 | F9: 45107 | G9: =B9<=Assumptions!$C$7 -> TRUE
B10: 7 | C10: 2023 | D10: 3 | E10: Q3 2023 | F10: 45199 | G10: =B10<=Assumptions!$C$7 -> TRUE
B11: 8 | C11: 2023 | D11: 4 | E11: Q4 2023 | F11: 45291 | G11: =B11<=Assumptions!$C$7 -> TRUE
B12: 9 | C12: 2024 | D12: 1 | E12: Q1 2024 | F12: 45382 | G12: =B12<=Assumptions!$C$7 -> TRUE
B13: 10 | C13: 2024 | D13: 2 | E13: Q2 2024 | F13: 45473 | G13: =B13<=Assumptions!$C$7 -> TRUE
B14: 11 | C14: 2024 | D14: 3 | E14: Q3 2024 | F14: 45565 | G14: =B14<=Assumptions!$C$7 -> TRUE
B15: 12 | C15: 2024 | D15: 4 | E15: Q4 2024 | F15: 45657 | G15: =B15<=Assumptions!$C$7 -> TRUE
... B21: 18 | C21: 2026 | D21: 2 | E21: Q2 2026 | F21: 46203 | G21: =B21<=Assumptions!$C$7 -> FALSE

Sheet LP Register
A1: LP Register
A2: 15 limited partners, commitments summing to committed capital
B3: LP ID | C3: LP Name | D3: LP Type | E3: Commitment ($) | F3: Commitment %
B4: LP-01 | C4: Northbridge State Pension Fund | D4: Pension Fund | E4: 8000000 | F4: =E4/Assumptions!$C$5 -> 0.16
B5: LP-02 | C5: Meridian University Endowment | D5: Endowment | E5: 6000000 | F5: =E5/Assumptions!$C$5 -> 0.12
B6: LP-03 | C6: Harborview Insurance Co. | D6: Insurance Company | E6: 5500000 | F6: =E6/Assumptions!$C$5 -> 0.11
B7: LP-04 | C7: Cascade Partners Fund of Funds | D7: Fund of Funds | E7: 5000000 | F7: =E7/Assumptions!$C$5 -> 0.1
B8: LP-05 | C8: Elmwood Family Office | D8: Family Office | E8: 4000000 | F8: =E8/Assumptions!$C$5 -> 0.08
B9: LP-06 | C9: Tanager Sovereign Partners | D9: Sovereign Wealth Fund | E9: 4000000 | F9: =E9/Assumptions!$C$5 -> 0.08
B10: LP-07 | C10: Birchwood College Endowment | D10: Endowment | E10: 3000000 | F10: =E10/Assumptions!$C$5 -> 0.06
B11: LP-08 | C11: Kestrel Insurance Group | D11: Insurance Company | E11: 2500000 | F11: =E11/Assumptions!$C$5 -> 0.05
B12: LP-09 | C12: Wrenfield Family Office | D12: Family Office | E12: 2000000 | F12: =E12/Assumptions!$C$5 -> 0.04
B13: LP-10 | C13: Alder Street Foundation | D13: Foundation | E13: 2000000 | F13: =E13/Assumptions!$C$5 -> 0.04
B14: LP-11 | C14: Pinecrest Pension Trust | D14: Pension Fund | E14: 1800000 | F14: =E14/Assumptions!$C$5 -> 0.036
B15: LP-12 | C15: Ivywood Capital Partners (FoF) | D15: Fund of Funds | E15: 1500000 | F15: =E15/Assumptions!$C$5 -> 0.03
... B18: LP-15 | C18: Sable Foundation | D18: Foundation | E18: 1600000 | F18: =E18/Assumptions!$C$5 -> 0.032
C19: Total | E19: =SUM(E4:E18) -> 50000000 | F19: =SUM(F4:F18) -> 1
C20: =IF(E19=Assumptions!$C$5,"OK — ties to committed capital","ERROR — does not tie") -> OK — ties to committed capital

Sheet Portfolio Companies
A1: Portfolio Companies
A2: 10 investments made during the 3-year investment period
B3: Company ID | C3: Company Name | D3: Sector | E3: Invest Quarter # | F3: Invest Quarter | G3: Cost Basis ($) | H3: Notes
B4: PC-01 | C4: Vantage Robotics | D4: Industrial Tech | E4: 1 | F4: =INDEX(Quarters!$E:$E,MATCH(E4,Quarters!$B:$B,0)) -> Q1 2022 | G4: 6000000 | H4: Strong performer — full exit
B5: PC-02 | C5: Coastal Foods Group | D5: Consumer | E5: 2 | F5: =INDEX(Quarters!$E:$E,MATCH(E5,Quarters!$B:$B,0)) -> Q2 2022 | G5: 5500000 | H5: Steady grower — full exit
B6: PC-03 | C6: Nimbus Data Systems | D6: Software | E6: 3 | F6: =INDEX(Quarters!$E:$E,MATCH(E6,Quarters!$B:$B,0)) -> Q3 2022 | G6: 4500000 | H6: Written down — held at reduced value
B7: PC-04 | C7: Harbor Dental Partners | D7: Healthcare Services | E7: 4 | F7: =INDEX(Quarters!$E:$E,MATCH(E7,Quarters!$B:$B,0)) -> Q4 2022 | G7: 5000000 | H7: Dividend recap — partial realization, remainder held
B8: PC-05 | C8: Trailhead Outdoor Co. | D8: Consumer | E8: 5 | F8: =INDEX(Quarters!$E:$E,MATCH(E8,Quarters!$B:$B,0)) -> Q1 2023 | G8: 4000000 | H8: Below-plan growth — held
B9: PC-06 | C9: Summit Logistics | D9: Transportation | E9: 6 | F9: =INDEX(Quarters!$E:$E,MATCH(E9,Quarters!$B:$B,0)) -> Q2 2023 | G9: 5000000 | H9: Strong performer — full exit
B10: PC-07 | C10: BluePeak Software | D10: Software | E10: 7 | F10: =INDEX(Quarters!$E:$E,MATCH(E10,Quarters!$B:$B,0)) -> Q3 2023 | G10: 4500000 | H10: Steady grower — full exit
B11: PC-08 | C11: Ridgeline Materials | D11: Industrials | E11: 8 | F11: =INDEX(Quarters!$E:$E,MATCH(E11,Quarters!$B:$B,0)) -> Q4 2023 | G11: 3500000 | H11: Below-plan growth — held
B12: PC-09 | C12: Fairmont Health Services | D12: Healthcare Services | E12: 9 | F12: =INDEX(Quarters!$E:$E,MATCH(E12,Quarters!$B:$B,0)) -> Q1 2024 | G12: 4000000 | H12: Steady grower — full exit
B13: PC-10 | C13: Alpine Consumer Brands | D13: Consumer | E13: 10 | F13: =INDEX(Quarters!$E:$E,MATCH(E13,Quarters!$B:$B,0)) -> Q2 2024 | G13: 3500000 | H13: Steady grower — full exit
C14: Total invested at cost | G14: =SUM(G4:G13) -> 45500000

Sheet Portfolio Marks
A1: Portfolio Marks
A2: Quarterly fair value marks and exit/recap events, by company
B3: Company ID | C3: Company Name | D3: Qtr # | E3: Quarter | F3: Cost Basis ($, BOP) | G3: Fair Value ($) | H3: Event Type | I3: % Realized | J3: Proceeds ($) | K3: Realized Cost Basis ($) | L3: Realized Gain ($)
B4: PC-01 | C4: Vantage Robotics | D4: 1 | E4: =INDEX(Quarters!$E:$E,MATCH(D4,Quarters!$B:$B,0)) -> Q1 2022 | F4: 6000000 | G4: 6000000 | J4: 0 | K4: 0 | L4: =J4-K4 -> 0
B5: PC-01 | C5: Vantage Robotics | D5: 2 | E5: =INDEX(Quarters!$E:$E,MATCH(D5,Quarters!$B:$B,0)) -> Q2 2022 | F5: 6000000 | G5: 6657424.5 | J5: 0 | K5: 0 | L5: =J5-K5 -> 0
B6: PC-01 | C6: Vantage Robotics | D6: 3 | E6: =INDEX(Quarters!$E:$E,MATCH(D6,Quarters!$B:$B,0)) -> Q3 2022 | F6: 6000000 | G6: 7252599.9 | J6: 0 | K6: 0 | L6: =J6-K6 -> 0
B7: PC-01 | C7: Vantage Robotics | D7: 4 | E7: =INDEX(Quarters!$E:$E,MATCH(D7,Quarters!$B:$B,0)) -> Q4 2022 | F7: 6000000 | G7: 8095763.7 | J7: 0 | K7: 0 | L7: =J7-K7 -> 0
B8: PC-01 | C8: Vantage Robotics | D8: 5 | E8: =INDEX(Quarters!$E:$E,MATCH(D8,Quarters!$B:$B,0)) -> Q1 2023 | F8: 6000000 | G8: 9060037.7 | J8: 0 | K8: 0 | L8: =J8-K8 -> 0
B9: PC-01 | C9: Vantage Robotics | D9: 6 | E9: =INDEX(Quarters!$E:$E,MATCH(D9,Quarters!$B:$B,0)) -> Q2 2023 | F9: 6000000 | G9: 9746194.9 | J9: 0 | K9: 0 | L9: =J9-K9 -> 0
B10: PC-01 | C10: Vantage Robotics | D10: 7 | E10: =INDEX(Quarters!$E:$E,MATCH(D10,Quarters!$B:$B,0)) -> Q3 2023 | F10: 6000000 | G10: 10579176 | J10: 0 | K10: 0 | L10: =J10-K10 -> 0
B11: PC-01 | C11: Vantage Robotics | D11: 8 | E11: =INDEX(Quarters!$E:$E,MATCH(D11,Quarters!$B:$B,0)) -> Q4 2023 | F11: 6000000 | G11: 11710276 | J11: 0 | K11: 0 | L11: =J11-K11 -> 0
B12: PC-01 | C12: Vantage Robotics | D12: 9 | E12: =INDEX(Quarters!$E:$E,MATCH(D12,Quarters!$B:$B,0)) -> Q1 2024 | F12: 6000000 | G12: 12884306 | J12: 0 | K12: 0 | L12: =J12-K12 -> 0
B13: PC-01 | C13: Vantage Robotics | D13: 10 | E13: =INDEX(Quarters!$E:$E,MATCH(D13,Quarters!$B:$B,0)) -> Q2 2024 | F13: 6000000 | G13: 14233911 | J13: 0 | K13: 0 | L13: =J13-K13 -> 0
B14: PC-01 | C14: Vantage Robotics | D14: 11 | E14: =INDEX(Quarters!$E:$E,MATCH(D14,Quarters!$B:$B,0)) -> Q3 2024 | F14: 6000000 | G14: 15546339 | J14: 0 | K14: 0 | L14: =J14-K14 -> 0
B15: PC-01 | C15: Vantage Robotics | D15: 12 | E15: =INDEX(Quarters!$E:$E,MATCH(D15,Quarters!$B:$B,0)) -> Q4 2024 | F15: 6000000 | G15: 17383776 | J15: 0 | K15: 0 | L15: =J15-K15 -> 0
B16: PC-01 | C16: Vantage Robotics | D16: 13 | E16: =INDEX(Quarters!$E:$E,MATCH(D16,Quarters!$B:$B,0)) -> Q1 2025 | F16: 6000000 | G16: 19411887 | H16: full_exit | I16: 1 | J16: 19411887 | K16: 6000000 | L16: =J16-K16 -> 13411887
B17: PC-02 | C17: Coastal Foods Group | D17: 2 | E17: =INDEX(Quarters!$E:$E,MATCH(D17,Quarters!$B:$B,0)) -> Q2 2022 | F17: 5500000 | G17: 5500000 | J17: 0 | K17: 0 | L17: =J17-K17 -> 0
B18: PC-02 | C18: Coastal Foods Group | D18: 3 | E18: =INDEX(Quarters!$E:$E,MATCH(D18,Quarters!$B:$B,0)) -> Q3 2022 | F18: 5500000 | G18: 5801358 | J18: 0 | K18: 0 | L18: =J18-K18 -> 0
B19: PC-02 | C19: Coastal Foods Group | D19: 4 | E19: =INDEX(Quarters!$E:$E,MATCH(D19,Quarters!$B:$B,0)) -> Q4 2022 | F19: 5500000 | G19: 6193105.7 | J19: 0 | K19: 0 | L19: =J19-K19 -> 0
B20: PC-02 | C20: Coastal Foods Group | D20: 5 | E20: =INDEX(Quarters!$E:$E,MATCH(D20,Quarters!$B:$B,0)) -> Q1 2023 | F20: 5500000 | G20: 6562277.4 | J20: 0 | K20: 0 | L20: =J20-K20 -> 0
B21: PC-02 | C21: Coastal Foods Group | D21: 6 | E21: =INDEX(Quarters!$E:$E,MATCH(D21,Quarters!$B:$B,0)) -> Q2 2023 | F21: 5500000 | G21: 6848973.4 | J21: 0 | K21: 0 | L21: =J21-K21 -> 0
B22: PC-02 | C22: Coastal Foods Group | D22: 7 | E22: =INDEX(Quarters!$E:$E,MATCH(D22,Quarters!$B:$B,0)) -> Q3 2023 | F22: 5500000 | G22: 7249124.8 | J22: 0 | K22: 0 | L22: =J22-K22 -> 0
B23: PC-02 | C23: Coastal Foods Group | D23: 8 | E23: =INDEX(Quarters!$E:$E,MATCH(D23,Quarters!$B:$B,0)) -> Q4 2023 | F23: 5500000 | G23: 7557164.8 | J23: 0 | K23: 0 | L23: =J23-K23 -> 0
B24: PC-02 | C24: Coastal Foods Group | D24: 9 | E24: =INDEX(Quarters!$E:$E,MATCH(D24,Quarters!$B:$B,0)) -> Q1 2024 | F24: 5500000 | G24: 8044914.8 | J24: 0 | K24: 0 | L24: =J24-K24 -> 0
B25: PC-02 | C25: Coastal Foods Group | D25: 10 | E25: =INDEX(Quarters!$E:$E,MATCH(D25,Quarters!$B:$B,0)) -> Q2 2024 | F25: 5500000 | G25: 8474520.4 | J25: 0 | K25: 0 | L25: =J25-K25 -> 0
B26: PC-02 | C26: Coastal Foods Group | D26: 11 | E26: =INDEX(Quarters!$E:$E,MATCH(D26,Quarters!$B:$B,0)) -> Q3 2024 | F26: 5500000 | G26: 8913345.1 | J26: 0 | K26: 0 | L26: =J26-K26 -> 0
B27: PC-02 | C27: Coastal Foods Group | D27: 12 | E27: =INDEX(Quarters!$E:$E,MATCH(D27,Quarters!$B:$B,0)) -> Q4 2024 | F27: 5500000 | G27: 9321833.4 | J27: 0 | K27: 0 | L27: =J27-K27 -> 0
B28: PC-02 | C28: Coastal Foods Group | D28: 13 | E28: =INDEX(Quarters!$E:$E,MATCH(D28,Quarters!$B:$B,0)) -> Q1 2025 | F28: 5500000 | G28: 9961968.3 | J28: 0 | K28: 0 | L28: =J28-K28 -> 0
B29: PC-02 | C29: Coastal Foods Group | D29: 14 | E29: =INDEX(Quarters!$E:$E,MATCH(D29,Quarters!$B:$B,0)) -> Q2 2025 | F29: 5500000 | G29: 10481442 | J29: 0 | K29: 0 | L29: =J29-K29 -> 0
B30: PC-02 | C30: Coastal Foods Group | D30: 15 | E30: =INDEX(Quarters!$E:$E,MATCH(D30,Quarters!$B:$B,0)) -> Q3 2025 | F30: 5500000 | G30: 10993566 | H30: full_exit | I30: 1 | J30: 10993566 | K30: 5500000 | L30: =J30-K30 -> 5493565.5
B31: PC-03 | C31: Nimbus Data Systems | D31: 3 | E31: =INDEX(Quarters!$E:$E,MATCH(D31,Quarters!$B:$B,0)) -> Q3 2022 | F31: 4500000 | G31: 4500000 | J31: 0 | K31: 0 | L31: =J31-K31 -> 0
B32: PC-03 | C32: Nimbus Data Systems | D32: 4 | E32: =INDEX(Quarters!$E:$E,MATCH(D32,Quarters!$B:$B,0)) -> Q4 2022 | F32: 4500000 | G32: 4273731 | J32: 0 | K32: 0 | L32: =J32-K32 -> 0
B33: PC-03 | C33: Nimbus Data Systems | D33: 5 | E33: =INDEX(Quarters!$E:$E,MATCH(D33,Quarters!$B:$B,0)) -> Q1 2023 | F33: 4500000 | G33: 4115537.3 | J33: 0 | K33: 0 | L33: =J33-K33 -> 0
B34: PC-03 | C34: Nimbus Data Systems | D34: 6 | E34: =INDEX(Quarters!$E:$E,MATCH(D34,Quarters!$B:$B,0)) -> Q2 2023 | F34: 4500000 | G34: 3952898.1 | J34: 0 | K34: 0 | L34: =J34-K34 -> 0
B35: PC-03 | C35: Nimbus Data Systems | D35: 7 | E35: =INDEX(Quarters!$E:$E,MATCH(D35,Quarters!$B:$B,0)) -> Q3 2023 | F35: 4500000 | G35: 3799490 | J35: 0 | K35: 0 | L35: =J35-K35 -> 0
B36: PC-03 | C36: Nimbus Data Systems | D36: 8 | E36: =INDEX(Quarters!$E:$E,MATCH(D36,Quarters!$B:$B,0)) -> Q4 2023 | F36: 4500000 | G36: 3653066.5 | J36: 0 | K36: 0 | L36: =J36-K36 -> 0
B37: PC-03 | C37: Nimbus Data Systems | D37: 9 | E37: =INDEX(Quarters!$E:$E,MATCH(D37,Quarters!$B:$B,0)) -> Q1 2024 | F37: 4500000 | G37: 3606032.2 | J37: 0 | K37: 0 | L37: =J37-K37 -> 0
B38: PC-03 | C38: Nimbus Data Systems | D38: 10 | E38: =INDEX(Quarters!$E:$E,MATCH(D38,Quarters!$B:$B,0)) -> Q2 2024 | F38: 4500000 | G38: 3421777.6 | J38: 0 | K38: 0 | L38: =J38-K38 -> 0
B39: PC-03 | C39: Nimbus Data Systems | D39: 11 | E39: =INDEX(Quarters!$E:$E,MATCH(D39,Quarters!$B:$B,0)) -> Q3 2024 | F39: 4500000 | G39: 3405070.3 | J39: 0 | K39: 0 | L39: =J39-K39 -> 0
B40: PC-03 | C40: Nimbus Data Systems | D40: 12 | E40: =INDEX(Quarters!$E:$E,MATCH(D40,Quarters!$B:$B,0)) -> Q4 2024 | F40: 4500000 | G40: 3428135.6 | J40: 0 | K40: 0 | L40: =J40-K40 -> 0
...

Sheet Mgmt Fee Schedule
A1: Management Fee Schedule
A2: 2% of committed capital during the investment period; 2% of remaining invested cost thereafter
B3: Qtr # | C3: Quarter | D3: In Investment Period | E3: Fee Basis ($) | F3: Fee Basis | G3: Management Fee ($)
B4: 1 | C4: =Quarters!$E$4 -> Q1 2022 | D4: =Quarters!$G$4 -> TRUE | E4: =IF(D4,Assumptions!$C$5,SUMIFS('Portfolio Marks'!$F:$F,'Portfolio Marks'!$D:$D,B4-1)) -> 50000000 | F4: =IF(D4,"Committed capital","Invested cost (step-down)") -> Committed capital | G4: =E4*Assumptions!$C$9/4 -> 250000
B5: 2 | C5: =Quarters!$E$5 -> Q2 2022 | D5: =Quarters!$G$5 -> TRUE | E5: =IF(D5,Assumptions!$C$5,SUMIFS('Portfolio Marks'!$F:$F,'Portfolio Marks'!$D:$D,B5-1)) -> 50000000 | F5: =IF(D5,"Committed capital","Invested cost (step-down)") -> Committed capital | G5: =E5*Assumptions!$C$9/4 -> 250000
B6: 3 | C6: =Quarters!$E$6 -> Q3 2022 | D6: =Quarters!$G$6 -> TRUE | E6: =IF(D6,Assumptions!$C$5,SUMIFS('Portfolio Marks'!$F:$F,'Portfolio Marks'!$D:$D,B6-1)) -> 50000000 | F6: =IF(D6,"Committed capital","Invested cost (step-down)") -> Committed capital | G6: =E6*Assumptions!$C$9/4 -> 250000
B7: 4 | C7: =Quarters!$E$7 -> Q4 2022 | D7: =Quarters!$G$7 -> TRUE | E7: =IF(D7,Assumptions!$C$5,SUMIFS('Portfolio Marks'!$F:$F,'Portfolio Marks'!$D:$D,B7-1)) -> 50000000 | F7: =IF(D7,"Committed capital","Invested cost (step-down)") -> Committed capital | G7: =E7*Assumptions!$C$9/4 -> 250000
B8: 5 | C8: =Quarters!$E$8 -> Q1 2023 | D8: =Quarters!$G$8 -> TRUE | E8: =IF(D8,Assumptions!$C$5,SUMIFS('Portfolio Marks'!$F:$F,'Portfolio Marks'!$D:$D,B8-1)) -> 50000000 | F8: =IF(D8,"Committed capital","Invested cost (step-down)") -> Committed capital | G8: =E8*Assumptions!$C$9/4 -> 250000
B9: 6 | C9: =Quarters!$E$9 -> Q2 2023 | D9: =Quarters!$G$9 -> TRUE | E9: =IF(D9,Assumptions!$C$5,SUMIFS('Portfolio Marks'!$F:$F,'Portfolio Marks'!$D:$D,B9-1)) -> 50000000 | F9: =IF(D9,"Committed capital","Invested cost (step-down)") -> Committed capital | G9: =E9*Assumptions!$C$9/4 -> 250000
B10: 7 | C10: =Quarters!$E$10 -> Q3 2023 | D10: =Quarters!$G$10 -> TRUE | E10: =IF(D10,Assumptions!$C$5,SUMIFS('Portfolio Marks'!$F:$F,'Portfolio Marks'!$D:$D,B10-1)) -> 50000000 | F10: =IF(D10,"Committed capital","Invested cost (step-down)") -> Committed capital | G10: =E10*Assumptions!$C$9/4 -> 250000
B11: 8 | C11: =Quarters!$E$11 -> Q4 2023 | D11: =Quarters!$G$11 -> TRUE | E11: =IF(D11,Assumptions!$C$5,SUMIFS('Portfolio Marks'!$F:$F,'Portfolio Marks'!$D:$D,B11-1)) -> 50000000 | F11: =IF(D11,"Committed capital","Invested cost (step-down)") -> Committed capital | G11: =E11*Assumptions!$C$9/4 -> 250000
B12: 9 | C12: =Quarters!$E$12 -> Q1 2024 | D12: =Quarters!$G$12 -> TRUE | E12: =IF(D12,Assumptions!$C$5,SUMIFS('Portfolio Marks'!$F:$F,'Portfolio Marks'!$D:$D,B12-1)) -> 50000000 | F12: =IF(D12,"Committed capital","Invested cost (step-down)") -> Committed capital | G12: =E12*Assumptions!$C$9/4 -> 250000
B13: 10 | C13: =Quarters!$E$13 -> Q2 2024 | D13: =Quarters!$G$13 -> TRUE | E13: =IF(D13,Assumptions!$C$5,SUMIFS('Portfolio Marks'!$F:$F,'Portfolio Marks'!$D:$D,B13-1)) -> 50000000 | F13: =IF(D13,"Committed capital","Invested cost (step-down)") -> Committed capital | G13: =E13*Assumptions!$C$9/4 -> 250000
B14: 11 | C14: =Quarters!$E$14 -> Q3 2024 | D14: =Quarters!$G$14 -> TRUE | E14: =IF(D14,Assumptions!$C$5,SUMIFS('Portfolio Marks'!$F:$F,'Portfolio Marks'!$D:$D,B14-1)) -> 50000000 | F14: =IF(D14,"Committed capital","Invested cost (step-down)") -> Committed capital | G14: =E14*Assumptions!$C$9/4 -> 250000
B15: 12 | C15: =Quarters!$E$15 -> Q4 2024 | D15: =Quarters!$G$15 -> TRUE | E15: =IF(D15,Assumptions!$C$5,SUMIFS('Portfolio Marks'!$F:$F,'Portfolio Marks'!$D:$D,B15-1)) -> 50000000 | F15: =IF(D15,"Committed capital","Invested cost (step-down)") -> Committed capital | G15: =E15*Assumptions!$C$9/4 -> 250000
B16: 13 | C16: =Quarters!$E$16 -> Q1 2025 | D16: =Quarters!$G$16 -> FALSE | E16: =IF(D16,Assumptions!$C$5,SUMIFS('Portfolio Marks'!$F:$F,'Portfolio Marks'!$D:$D,B16-1)) -> 45500000 | F16: =IF(D16,"Committed capital","Invested cost (step-down)") -> Invested cost (step-down) | G16: =E16*Assumptions!$C$9/4 -> 227500
B17: 14 | C17: =Quarters!$E$17 -> Q2 2025 | D17: =Quarters!$G$17 -> FALSE | E17: =IF(D17,Assumptions!$C$5,SUMIFS('Portfolio Marks'!$F:$F,'Portfolio Marks'!$D:$D,B17-1)) -> 45500000 | F17: =IF(D17,"Committed capital","Invested cost (step-down)") -> Invested cost (step-down) | G17: =E17*Assumptions!$C$9/4 -> 227500
B18: 15 | C18: =Quarters!$E$18 -> Q3 2025 | D18: =Quarters!$G$18 -> FALSE | E18: =IF(D18,Assumptions!$C$5,SUMIFS('Portfolio Marks'!$F:$F,'Portfolio Marks'!$D:$D,B18-1)) -> 39500000 | F18: =IF(D18,"Committed capital","Invested cost (step-down)") -> Invested cost (step-down) | G18: =E18*Assumptions!$C$9/4 -> 197500
B19: 16 | C19: =Quarters!$E$19 -> Q4 2025 | D19: =Quarters!$G$19 -> FALSE | E19: =IF(D19,Assumptions!$C$5,SUMIFS('Portfolio Marks'!$F:$F,'Portfolio Marks'!$D:$D,B19-1)) -> 39500000 | F19: =IF(D19,"Committed capital","Invested cost (step-down)") -> Invested cost (step-down) | G19: =E19*Assumptions!$C$9/4 -> 197500
B20: 17 | C20: =Quarters!$E$20 -> Q1 2026 | D20: =Quarters!$G$20 -> FALSE | E20: =IF(D20,Assumptions!$C$5,SUMIFS('Portfolio Marks'!$F:$F,'Portfolio Marks'!$D:$D,B20-1)) -> 34000000 | F20: =IF(D20,"Committed capital","Invested cost (step-down)") -> Invested cost (step-down) | G20: =E20*Assumptions!$C$9/4 -> 170000
B21: 18 | C21: =Quarters!$E$21 -> Q2 2026 | D21: =Quarters!$G$21 -> FALSE | E21: =IF(D21,Assumptions!$C$5,SUMIFS('Portfolio Marks'!$F:$F,'Portfolio Marks'!$D:$D,B21-1)) -> 34000000 | F21: =IF(D21,"Committed capital","Invested cost (step-down)") -> Invested cost (step-down) | G21: =E21*Assumptions!$C$9/4 -> 170000

Sheet Capital Call Schedule
A1: Capital Call Schedule
A2: Fund-level quarterly capital calls — investment need + management fee
B3: Qtr # | C3: Quarter | D3: Investment Call ($) | E3: Mgmt Fee Call ($) | F3: Total Call ($) | G3: Cumulative Called ($)
B4: 1 | C4: =Quarters!$E$4 -> Q1 2022 | D4: =SUMIFS('Portfolio Companies'!$G:$G,'Portfolio Companies'!$E:$E,B4) -> 6000000 | E4: ='Mgmt Fee Schedule'!$G$4 -> 250000 | F4: =D4+E4 -> 6250000 | G4: =F4 -> 6250000
B5: 2 | C5: =Quarters!$E$5 -> Q2 2022 | D5: =SUMIFS('Portfolio Companies'!$G:$G,'Portfolio Companies'!$E:$E,B5) -> 5500000 | E5: ='Mgmt Fee Schedule'!$G$5 -> 250000 | F5: =D5+E5 -> 5750000 | G5: =G4+F5 -> 12000000
B6: 3 | C6: =Quarters!$E$6 -> Q3 2022 | D6: =SUMIFS('Portfolio Companies'!$G:$G,'Portfolio Companies'!$E:$E,B6) -> 4500000 | E6: ='Mgmt Fee Schedule'!$G$6 -> 250000 | F6: =D6+E6 -> 4750000 | G6: =G5+F6 -> 16750000
B7: 4 | C7: =Quarters!$E$7 -> Q4 2022 | D7: =SUMIFS('Portfolio Companies'!$G:$G,'Portfolio Companies'!$E:$E,B7) -> 5000000 | E7: ='Mgmt Fee Schedule'!$G$7 -> 250000 | F7: =D7+E7 -> 5250000 | G7: =G6+F7 -> 22000000
B8: 5 | C8: =Quarters!$E$8 -> Q1 2023 | D8: =SUMIFS('Portfolio Companies'!$G:$G,'Portfolio Companies'!$E:$E,B8) -> 4000000 | E8: ='Mgmt Fee Schedule'!$G$8 -> 250000 | F8: =D8+E8 -> 4250000 | G8: =G7+F8 -> 26250000
B9: 6 | C9: =Quarters!$E$9 -> Q2 2023 | D9: =SUMIFS('Portfolio Companies'!$G:$G,'Portfolio Companies'!$E:$E,B9) -> 5000000 | E9: ='Mgmt Fee Schedule'!$G$9 -> 250000 | F9: =D9+E9 -> 5250000 | G9: =G8+F9 -> 31500000
B10: 7 | C10: =Quarters!$E$10 -> Q3 2023 | D10: =SUMIFS('Portfolio Companies'!$G:$G,'Portfolio Companies'!$E:$E,B10) -> 4500000 | E10: ='Mgmt Fee Schedule'!$G$10 -> 250000 | F10: =D10+E10 -> 4750000 | G10: =G9+F10 -> 36250000
B11: 8 | C11: =Quarters!$E$11 -> Q4 2023 | D11: =SUMIFS('Portfolio Companies'!$G:$G,'Portfolio Companies'!$E:$E,B11) -> 3500000 | E11: ='Mgmt Fee Schedule'!$G$11 -> 250000 | F11: =D11+E11 -> 3750000 | G11: =G10+F11 -> 40000000
B12: 9 | C12: =Quarters!$E$12 -> Q1 2024 | D12: =SUMIFS('Portfolio Companies'!$G:$G,'Portfolio Companies'!$E:$E,B12) -> 4000000 | E12: ='Mgmt Fee Schedule'!$G$12 -> 250000 | F12: =D12+E12 -> 4250000 | G12: =G11+F12 -> 44250000
B13: 10 | C13: =Quarters!$E$13 -> Q2 2024 | D13: =SUMIFS('Portfolio Companies'!$G:$G,'Portfolio Companies'!$E:$E,B13) -> 3500000 | E13: ='Mgmt Fee Schedule'!$G$13 -> 250000 | F13: =D13+E13 -> 3750000 | G13: =G12+F13 -> 48000000
B14: 11 | C14: =Quarters!$E$14 -> Q3 2024 | D14: =SUMIFS('Portfolio Companies'!$G:$G,'Portfolio Companies'!$E:$E,B14) -> 0 | E14: ='Mgmt Fee Schedule'!$G$14 -> 250000 | F14: =D14+E14 -> 250000 | G14: =G13+F14 -> 48250000
B15: 12 | C15: =Quarters!$E$15 -> Q4 2024 | D15: =SUMIFS('Portfolio Companies'!$G:$G,'Portfolio Companies'!$E:$E,B15) -> 0 | E15: ='Mgmt Fee Schedule'!$G$15 -> 250000 | F15: =D15+E15 -> 250000 | G15: =G14+F15 -> 48500000
B16: 13 | C16: =Quarters!$E$16 -> Q1 2025 | D16: =SUMIFS('Portfolio Companies'!$G:$G,'Portfolio Companies'!$E:$E,B16) -> 0 | E16: ='Mgmt Fee Schedule'!$G$16 -> 227500 | F16: =D16+E16 -> 227500 | G16: =G15+F16 -> 48727500
B17: 14 | C17: =Quarters!$E$17 -> Q2 2025 | D17: =SUMIFS('Portfolio Companies'!$G:$G,'Portfolio Companies'!$E:$E,B17) -> 0 | E17: ='Mgmt Fee Schedule'!$G$17 -> 227500 | F17: =D17+E17 -> 227500 | G17: =G16+F17 -> 48955000
B18: 15 | C18: =Quarters!$E$18 -> Q3 2025 | D18: =SUMIFS('Portfolio Companies'!$G:$G,'Portfolio Companies'!$E:$E,B18) -> 0 | E18: ='Mgmt Fee Schedule'!$G$18 -> 197500 | F18: =D18+E18 -> 197500 | G18: =G17+F18 -> 49152500
B19: 16 | C19: =Quarters!$E$19 -> Q4 2025 | D19: =SUMIFS('Portfolio Companies'!$G:$G,'Portfolio Companies'!$E:$E,B19) -> 0 | E19: ='Mgmt Fee Schedule'!$G$19 -> 197500 | F19: =D19+E19 -> 197500 | G19: =G18+F19 -> 49350000
B20: 17 | C20: =Quarters!$E$20 -> Q1 2026 | D20: =SUMIFS('Portfolio Companies'!$G:$G,'Portfolio Companies'!$E:$E,B20) -> 0 | E20: ='Mgmt Fee Schedule'!$G$20 -> 170000 | F20: =D20+E20 -> 170000 | G20: =G19+F20 -> 49520000
B21: 18 | C21: =Quarters!$E$21 -> Q2 2026 | D21: =SUMIFS('Portfolio Companies'!$G:$G,'Portfolio Companies'!$E:$E,B21) -> 0 | E21: ='Mgmt Fee Schedule'!$G$21 -> 170000 | F21: =D21+E21 -> 170000 | G21: =G20+F21 -> 49690000
C22: Total / Unfunded Commitment | F22: =SUM(F4:F21) -> 49690000 | G22: =Assumptions!$C$5-G21 -> 310000
C23: (Unfunded commitment remaining)

Sheet Distribution Waterfall
A1: Distribution Waterfall
A2: European (whole-fund) waterfall, run cumulatively by quarter: Return of Capital -> Preferred Return -> GP Catch-up -> 80/20 Carry Split
B3: Qtr # | C3: Quarter | D3: Distributable ($) | E3: Cum. Contributions (BOP) | F3: Cum. Contributions (EOP) | G3: Cum. ROC Distributed (BOP) | H3: Preferred Accrual (Qtr) | I3: Cum. Preferred Accrued (EOP) | J3: Cum. Preferred Paid (BOP) | K3: Cum. GP Catch-up Paid (BOP) | L3: Tier 1: Return of Capital | M3: Cum. ROC Distributed (EOP) | N3: Tier 2: Preferred Return | O3: Cum. Preferred Paid (EOP) | P3: Target Cum. Catch-up (Total) | Q3: Tier 3: GP Catch-up | R3: Cum. GP Catch-up Paid (EOP) | S3: Tier 4: Carry (Total) | T3: Tier 4: Carry to LPs (80%) | U3: Tier 4: Carry to GP (20%) | V3: Total to LPs | W3: Total to GP
B4: 1 | C4: =Quarters!$E$4 -> Q1 2022 | D4: =SUMIFS('Portfolio Marks'!$J:$J,'Portfolio Marks'!$D:$D,B4) -> 0 | E4: 0 | F4: =E4+'Capital Call Schedule'!$F$4 -> 6250000 | G4: 0 | H4: =(E4-G4)*Assumptions!$C$11/4 -> 0 | I4: =H4 -> 0 | J4: 0 | K4: 0 | L4: =MIN(D4,MAX(F4-G4,0)) -> 0 | M4: =G4+L4 -> 0 | N4: =MIN(D4-L4,MAX(I4-J4,0)) -> 0 | O4: =J4+N4 -> 0 | P4: =(Assumptions!$C$13/(1-Assumptions!$C$13))*O4 -> 0 | Q4: =MIN(D4-L4-N4,MAX(P4-K4,0)) -> 0 | R4: =K4+Q4 -> 0 | S4: =D4-L4-N4-Q4 -> 0 | T4: =S4*(1-Assumptions!$C$13) -> 0 | U4: =S4*Assumptions!$C$13 -> 0 | V4: =L4+N4+T4 -> 0 | W4: =Q4+U4 -> 0
B5: 2 | C5: =Quarters!$E$5 -> Q2 2022 | D5: =SUMIFS('Portfolio Marks'!$J:$J,'Portfolio Marks'!$D:$D,B5) -> 0 | E5: =F4 -> 6250000 | F5: =E5+'Capital Call Schedule'!$F$5 -> 12000000 | G5: =M4 -> 0 | H5: =(E5-G5)*Assumptions!$C$11/4 -> 125000 | I5: =I4+H5 -> 125000 | J5: =O4 -> 0 | K5: =R4 -> 0 | L5: =MIN(D5,MAX(F5-G5,0)) -> 0 | M5: =G5+L5 -> 0 | N5: =MIN(D5-L5,MAX(I5-J5,0)) -> 0 | O5: =J5+N5 -> 0 | P5: =(Assumptions!$C$13/(1-Assumptions!$C$13))*O5 -> 0 | Q5: =MIN(D5-L5-N5,MAX(P5-K5,0)) -> 0 | R5: =K5+Q5 -> 0 | S5: =D5-L5-N5-Q5 -> 0 | T5: =S5*(1-Assumptions!$C$13) -> 0 | U5: =S5*Assumptions!$C$13 -> 0 | V5: =L5+N5+T5 -> 0 | W5: =Q5+U5 -> 0
B6: 3 | C6: =Quarters!$E$6 -> Q3 2022 | D6: =SUMIFS('Portfolio Marks'!$J:$J,'Portfolio Marks'!$D:$D,B6) -> 0 | E6: =F5 -> 12000000 | F6: =E6+'Capital Call Schedule'!$F$6 -> 16750000 | G6: =M5 -> 0 | H6: =(E6-G6)*Assumptions!$C$11/4 -> 240000 | I6: =I5+H6 -> 365000 | J6: =O5 -> 0 | K6: =R5 -> 0 | L6: =MIN(D6,MAX(F6-G6,0)) -> 0 | M6: =G6+L6 -> 0 | N6: =MIN(D6-L6,MAX(I6-J6,0)) -> 0 | O6: =J6+N6 -> 0 | P6: =(Assumptions!$C$13/(1-Assumptions!$C$13))*O6 -> 0 | Q6: =MIN(D6-L6-N6,MAX(P6-K6,0)) -> 0 | R6: =K6+Q6 -> 0 | S6: =D6-L6-N6-Q6 -> 0 | T6: =S6*(1-Assumptions!$C$13) -> 0 | U6: =S6*Assumptions!$C$13 -> 0 | V6: =L6+N6+T6 -> 0 | W6: =Q6+U6 -> 0
B7: 4 | C7: =Quarters!$E$7 -> Q4 2022 | D7: =SUMIFS('Portfolio Marks'!$J:$J,'Portfolio Marks'!$D:$D,B7) -> 0 | E7: =F6 -> 16750000 | F7: =E7+'Capital Call Schedule'!$F$7 -> 22000000 | G7: =M6 -> 0 | H7: =(E7-G7)*Assumptions!$C$11/4 -> 335000 | I7: =I6+H7 -> 700000 | J7: =O6 -> 0 | K7: =R6 -> 0 | L7: =MIN(D7,MAX(F7-G7,0)) -> 0 | M7: =G7+L7 -> 0 | N7: =MIN(D7-L7,MAX(I7-J7,0)) -> 0 | O7: =J7+N7 -> 0 | P7: =(Assumptions!$C$13/(1-Assumptions!$C$13))*O7 -> 0 | Q7: =MIN(D7-L7-N7,MAX(P7-K7,0)) -> 0 | R7: =K7+Q7 -> 0 | S7: =D7-L7-N7-Q7 -> 0 | T7: =S7*(1-Assumptions!$C$13) -> 0 | U7: =S7*Assumptions!$C$13 -> 0 | V7: =L7+N7+T7 -> 0 | W7: =Q7+U7 -> 0
B8: 5 | C8: =Quarters!$E$8 -> Q1 2023 | D8: =SUMIFS('Portfolio Marks'!$J:$J,'Portfolio Marks'!$D:$D,B8) -> 0 | E8: =F7 -> 22000000 | F8: =E8+'Capital Call Schedule'!$F$8 -> 26250000 | G8: =M7 -> 0 | H8: =(E8-G8)*Assumptions!$C$11/4 -> 440000 | I8: =I7+H8 -> 1140000 | J8: =O7 -> 0 | K8: =R7 -> 0 | L8: =MIN(D8,MAX(F8-G8,0)) -> 0 | M8: =G8+L8 -> 0 | N8: =MIN(D8-L8,MAX(I8-J8,0)) -> 0 | O8: =J8+N8 -> 0 | P8: =(Assumptions!$C$13/(1-Assumptions!$C$13))*O8 -> 0 | Q8: =MIN(D8-L8-N8,MAX(P8-K8,0)) -> 0 | R8: =K8+Q8 -> 0 | S8: =D8-L8-N8-Q8 -> 0 | T8: =S8*(1-Assumptions!$C$13) -> 0 | U8: =S8*Assumptions!$C$13 -> 0 | V8: =L8+N8+T8 -> 0 | W8: =Q8+U8 -> 0
B9: 6 | C9: =Quarters!$E$9 -> Q2 2023 | D9: =SUMIFS('Portfolio Marks'!$J:$J,'Portfolio Marks'!$D:$D,B9) -> 0 | E9: =F8 -> 26250000 | F9: =E9+'Capital Call Schedule'!$F$9 -> 31500000 | G9: =M8 -> 0 | H9: =(E9-G9)*Assumptions!$C$11/4 -> 525000 | I9: =I8+H9 -> 1665000 | J9: =O8 -> 0 | K9: =R8 -> 0 | L9: =MIN(D9,MAX(F9-G9,0)) -> 0 | M9: =G9+L9 -> 0 | N9: =MIN(D9-L9,MAX(I9-J9,0)) -> 0 | O9: =J9+N9 -> 0 | P9: =(Assumptions!$C$13/(1-Assumptions!$C$13))*O9 -> 0 | Q9: =MIN(D9-L9-N9,MAX(P9-K9,0)) -> 0 | R9: =K9+Q9 -> 0 | S9: =D9-L9-N9-Q9 -> 0 | T9: =S9*(1-Assumptions!$C$13) -> 0 | U9: =S9*Assumptions!$C$13 -> 0 | V9: =L9+N9+T9 -> 0 | W9: =Q9+U9 -> 0
B10: 7 | C10: =Quarters!$E$10 -> Q3 2023 | D10: =SUMIFS('Portfolio Marks'!$J:$J,'Portfolio Marks'!$D:$D,B10) -> 0 | E10: =F9 -> 31500000 | F10: =E10+'Capital Call Schedule'!$F$10 -> 36250000 | G10: =M9 -> 0 | H10: =(E10-G10)*Assumptions!$C$11/4 -> 630000 | I10: =I9+H10 -> 2295000 | J10: =O9 -> 0 | K10: =R9 -> 0 | L10: =MIN(D10,MAX(F10-G10,0)) -> 0 | M10: =G10+L10 -> 0 | N10: =MIN(D10-L10,MAX(I10-J10,0)) -> 0 | O10: =J10+N10 -> 0 | P10: =(Assumptions!$C$13/(1-Assumptions!$C$13))*O10 -> 0 | Q10: =MIN(D10-L10-N10,MAX(P10-K10,0)) -> 0 | R10: =K10+Q10 -> 0 | S10: =D10-L10-N10-Q10 -> 0 | T10: =S10*(1-Assumptions!$C$13) -> 0 | U10: =S10*Assumptions!$C$13 -> 0 | V10: =L10+N10+T10 -> 0 | W10: =Q10+U10 -> 0
B11: 8 | C11: =Quarters!$E$11 -> Q4 2023 | D11: =SUMIFS('Portfolio Marks'!$J:$J,'Portfolio Marks'!$D:$D,B11) -> 0 | E11: =F10 -> 36250000 | F11: =E11+'Capital Call Schedule'!$F$11 -> 40000000 | G11: =M10 -> 0 | H11: =(E11-G11)*Assumptions!$C$11/4 -> 725000 | I11: =I10+H11 -> 3020000 | J11: =O10 -> 0 | K11: =R10 -> 0 | L11: =MIN(D11,MAX(F11-G11,0)) -> 0 | M11: =G11+L11 -> 0 | N11: =MIN(D11-L11,MAX(I11-J11,0)) -> 0 | O11: =J11+N11 -> 0 | P11: =(Assumptions!$C$13/(1-Assumptions!$C$13))*O11 -> 0 | Q11: =MIN(D11-L11-N11,MAX(P11-K11,0)) -> 0 | R11: =K11+Q11 -> 0 | S11: =D11-L11-N11-Q11 -> 0 | T11: =S11*(1-Assumptions!$C$13) -> 0 | U11: =S11*Assumptions!$C$13 -> 0 | V11: =L11+N11+T11 -> 0 | W11: =Q11+U11 -> 0
B12: 9 | C12: =Quarters!$E$12 -> Q1 2024 | D12: =SUMIFS('Portfolio Marks'!$J:$J,'Portfolio Marks'!$D:$D,B12) -> 0 | E12: =F11 -> 40000000 | F12: =E12+'Capital Call Schedule'!$F$12 -> 44250000 | G12: =M11 -> 0 | H12: =(E12-G12)*Assumptions!$C$11/4 -> 800000 | I12: =I11+H12 -> 3820000 | J12: =O11 -> 0 | K12: =R11 -> 0 | L12: =MIN(D12,MAX(F12-G12,0)) -> 0 | M12: =G12+L12 -> 0 | N12: =MIN(D12-L12,MAX(I12-J12,0)) -> 0 | O12: =J12+N12 -> 0 | P12: =(Assumptions!$C$13/(1-Assumptions!$C$13))*O12 -> 0 | Q12: =MIN(D12-L12-N12,MAX(P12-K12,0)) -> 0 | R12: =K12+Q12 -> 0 | S12: =D12-L12-N12-Q12 -> 0 | T12: =S12*(1-Assumptions!$C$13) -> 0 | U12: =S12*Assumptions!$C$13 -> 0 | V12: =L12+N12+T12 -> 0 | W12: =Q12+U12 -> 0
B13: 10 | C13: =Quarters!$E$13 -> Q2 2024 | D13: =SUMIFS('Portfolio Marks'!$J:$J,'Portfolio Marks'!$D:$D,B13) -> 0 | E13: =F12 -> 44250000 | F13: =E13+'Capital Call Schedule'!$F$13 -> 48000000 | G13: =M12 -> 0 | H13: =(E13-G13)*Assumptions!$C$11/4 -> 885000 | I13: =I12+H13 -> 4705000 | J13: =O12 -> 0 | K13: =R12 -> 0 | L13: =MIN(D13,MAX(F13-G13,0)) -> 0 | M13: =G13+L13 -> 0 | N13: =MIN(D13-L13,MAX(I13-J13,0)) -> 0 | O13: =J13+N13 -> 0 | P13: =(Assumptions!$C$13/(1-Assumptions!$C$13))*O13 -> 0 | Q13: =MIN(D13-L13-N13,MAX(P13-K13,0)) -> 0 | R13: =K13+Q13 -> 0 | S13: =D13-L13-N13-Q13 -> 0 | T13: =S13*(1-Assumptions!$C$13) -> 0 | U13: =S13*Assumptions!$C$13 -> 0 | V13: =L13+N13+T13 -> 0 | W13: =Q13+U13 -> 0
B14: 11 | C14: =Quarters!$E$14 -> Q3 2024 | D14: =SUMIFS('Portfolio Marks'!$J:$J,'Portfolio Marks'!$D:$D,B14) -> 0 | E14: =F13 -> 48000000 | F14: =E14+'Capital Call Schedule'!$F$14 -> 48250000 | G14: =M13 -> 0 | H14: =(E14-G14)*Assumptions!$C$11/4 -> 960000 | I14: =I13+H14 -> 5665000 | J14: =O13 -> 0 | K14: =R13 -> 0 | L14: =MIN(D14,MAX(F14-G14,0)) -> 0 | M14: =G14+L14 -> 0 | N14: =MIN(D14-L14,MAX(I14-J14,0)) -> 0 | O14: =J14+N14 -> 0 | P14: =(Assumptions!$C$13/(1-Assumptions!$C$13))*O14 -> 0 | Q14: =MIN(D14-L14-N14,MAX(P14-K14,0)) -> 0 | R14: =K14+Q14 -> 0 | S14: =D14-L14-N14-Q14 -> 0 | T14: =S14*(1-Assumptions!$C$13) -> 0 | U14: =S14*Assumptions!$C$13 -> 0 | V14: =L14+N14+T14 -> 0 | W14: =Q14+U14 -> 0
B15: 12 | C15: =Quarters!$E$15 -> Q4 2024 | D15: =SUMIFS('Portfolio Marks'!$J:$J,'Portfolio Marks'!$D:$D,B15) -> 0 | E15: =F14 -> 48250000 | F15: =E15+'Capital Call Schedule'!$F$15 -> 48500000 | G15: =M14 -> 0 | H15: =(E15-G15)*Assumptions!$C$11/4 -> 965000 | I15: =I14+H15 -> 6630000 | J15: =O14 -> 0 | K15: =R14 -> 0 | L15: =MIN(D15,MAX(F15-G15,0)) -> 0 | M15: =G15+L15 -> 0 | N15: =MIN(D15-L15,MAX(I15-J15,0)) -> 0 | O15: =J15+N15 -> 0 | P15: =(Assumptions!$C$13/(1-Assumptions!$C$13))*O15 -> 0 | Q15: =MIN(D15-L15-N15,MAX(P15-K15,0)) -> 0 | R15: =K15+Q15 -> 0 | S15: =D15-L15-N15-Q15 -> 0 | T15: =S15*(1-Assumptions!$C$13) -> 0 | U15: =S15*Assumptions!$C$13 -> 0 | V15: =L15+N15+T15 -> 0 | W15: =Q15+U15 -> 0
B16: 13 | C16: =Quarters!$E$16 -> Q1 2025 | D16: =SUMIFS('Portfolio Marks'!$J:$J,'Portfolio Marks'!$D:$D,B16) -> 19411887 | E16: =F15 -> 48500000 | F16: =E16+'Capital Call Schedule'!$F$16 -> 48727500 | G16: =M15 -> 0 | H16: =(E16-G16)*Assumptions!$C$11/4 -> 970000 | I16: =I15+H16 -> 7600000 | J16: =O15 -> 0 | K16: =R15 -> 0 | L16: =MIN(D16,MAX(F16-G16,0)) -> 19411887 | M16: =G16+L16 -> 19411887 | N16: =MIN(D16-L16,MAX(I16-J16,0)) -> 0 | O16: =J16+N16 -> 0 | P16: =(Assumptions!$C$13/(1-Assumptions!$C$13))*O16 -> 0 | Q16: =MIN(D16-L16-N16,MAX(P16-K16,0)) -> 0 | R16: =K16+Q16 -> 0 | S16: =D16-L16-N16-Q16 -> 0 | T16: =S16*(1-Assumptions!$C$13) -> 0 | U16: =S16*Assumptions!$C$13 -> 0 | V16: =L16+N16+T16 -> 19411887 | W16: =Q16+U16 -> 0
B17: 14 | C17: =Quarters!$E$17 -> Q2 2025 | D17: =SUMIFS('Portfolio Marks'!$J:$J,'Portfolio Marks'!$D:$D,B17) -> 0 | E17: =F16 -> 48727500 | F17: =E17+'Capital Call Schedule'!$F$17 -> 48955000 | G17: =M16 -> 19411887 | H17: =(E17-G17)*Assumptions!$C$11/4 -> 586312.26 | I17: =I16+H17 -> 8186312.3 | J17: =O16 -> 0 | K17: =R16 -> 0 | L17: =MIN(D17,MAX(F17-G17,0)) -> 0 | M17: =G17+L17 -> 19411887 | N17: =MIN(D17-L17,MAX(I17-J17,0)) -> 0 | O17: =J17+N17 -> 0 | P17: =(Assumptions!$C$13/(1-Assumptions!$C$13))*O17 -> 0 | Q17: =MIN(D17-L17-N17,MAX(P17-K17,0)) -> 0 | R17: =K17+Q17 -> 0 | S17: =D17-L17-N17-Q17 -> 0 | T17: =S17*(1-Assumptions!$C$13) -> 0 | U17: =S17*Assumptions!$C$13 -> 0 | V17: =L17+N17+T17 -> 0 | W17: =Q17+U17 -> 0
B18: 15 | C18: =Quarters!$E$18 -> Q3 2025 | D18: =SUMIFS('Portfolio Marks'!$J:$J,'Portfolio Marks'!$D:$D,B18) -> 10993566 | E18: =F17 -> 48955000 | F18: =E18+'Capital Call Schedule'!$F$18 -> 49152500 | G18: =M17 -> 19411887 | H18: =(E18-G18)*Assumptions!$C$11/4 -> 590862.26 | I18: =I17+H18 -> 8777174.5 | J18: =O17 -> 0 | K18: =R17 -> 0 | L18: =MIN(D18,MAX(F18-G18,0)) -> 10993566 | M18: =G18+L18 -> 30405453 | N18: =MIN(D18-L18,MAX(I18-J18,0)) -> 0 | O18: =J18+N18 -> 0 | P18: =(Assumptions!$C$13/(1-Assumptions!$C$13))*O18 -> 0 | Q18: =MIN(D18-L18-N18,MAX(P18-K18,0)) -> 0 | R18: =K18+Q18 -> 0 | S18: =D18-L18-N18-Q18 -> 0 | T18: =S18*(1-Assumptions!$C$13) -> 0 | U18: =S18*Assumptions!$C$13 -> 0 | V18: =L18+N18+T18 -> 10993566 | W18: =Q18+U18 -> 0
B19: 16 | C19: =Quarters!$E$19 -> Q4 2025 | D19: =SUMIFS('Portfolio Marks'!$J:$J,'Portfolio Marks'!$D:$D,B19) -> 0 | E19: =F18 -> 49152500 | F19: =E19+'Capital Call Schedule'!$F$19 -> 49350000 | G19: =M18 -> 30405453 | H19: =(E19-G19)*Assumptions!$C$11/4 -> 374940.95 | I19: =I18+H19 -> 9152115.5 | J19: =O18 -> 0 | K19: =R18 -> 0 | L19: =MIN(D19,MAX(F19-G19,0)) -> 0 | M19: =G19+L19 -> 30405453 | N19: =MIN(D19-L19,MAX(I19-J19,0)) -> 0 | O19: =J19+N19 -> 0 | P19: =(Assumptions!$C$13/(1-Assumptions!$C$13))*O19 -> 0 | Q19: =MIN(D19-L19-N19,MAX(P19-K19,0)) -> 0 | R19: =K19+Q19 -> 0 | S19: =D19-L19-N19-Q19 -> 0 | T19: =S19*(1-Assumptions!$C$13) -> 0 | U19: =S19*Assumptions!$C$13 -> 0 | V19: =L19+N19+T19 -> 0 | W19: =Q19+U19 -> 0
B20: 17 | C20: =Quarters!$E$20 -> Q1 2026 | D20: =SUMIFS('Portfolio Marks'!$J:$J,'Portfolio Marks'!$D:$D,B20) -> 14803879 | E20: =F19 -> 49350000 | F20: =E20+'Capital Call Schedule'!$F$20 -> 49520000 | G20: =M19 -> 30405453 | H20: =(E20-G20)*Assumptions!$C$11/4 -> 378890.95 | I20: =I19+H20 -> 9531006.4 | J20: =O19 -> 0 | K20: =R19 -> 0 | L20: =MIN(D20,MAX(F20-G20,0)) -> 14803879 | M20: =G20+L20 -> 45209331 | N20: =MIN(D20-L20,MAX(I20-J20,0)) -> 0 | O20: =J20+N20 -> 0 | P20: =(Assumptions!$C$13/(1-Assumptions!$C$13))*O20 -> 0 | Q20: =MIN(D20-L20-N20,MAX(P20-K20,0)) -> 0 | R20: =K20+Q20 -> 0 | S20: =D20-L20-N20-Q20 -> 0 | T20: =S20*(1-Assumptions!$C$13) -> 0 | U20: =S20*Assumptions!$C$13 -> 0 | V20: =L20+N20+T20 -> 14803879 | W20: =Q20+U20 -> 0
B21: 18 | C21: =Quarters!$E$21 -> Q2 2026 | D21: =SUMIFS('Portfolio Marks'!$J:$J,'Portfolio Marks'!$D:$D,B21) -> 19995229 | E21: =F20 -> 49520000 | F21: =E21+'Capital Call Schedule'!$F$21 -> 49690000 | G21: =M20 -> 45209331 | H21: =(E21-G21)*Assumptions!$C$11/4 -> 86213.375 | I21: =I20+H21 -> 9617219.8 | J21: =O20 -> 0 | K21: =R20 -> 0 | L21: =MIN(D21,MAX(F21-G21,0)) -> 4480668.7 | M21: =G21+L21 -> 49690000 | N21: =MIN(D21-L21,MAX(I21-J21,0)) -> 9617219.8 | O21: =J21+N21 -> 9617219.8 | P21: =(Assumptions!$C$13/(1-Assumptions!$C$13))*O21 -> 2404304.9 | Q21: =MIN(D21-L21-N21,MAX(P21-K21,0)) -> 2404304.9 | R21: =K21+Q21 -> 2404304.9 | S21: =D21-L21-N21-Q21 -> 3493035.7 | T21: =S21*(1-Assumptions!$C$13) -> 2794428.6 | U21: =S21*Assumptions!$C$13 -> 698607.14 | V21: =L21+N21+T21 -> 16892317 | W21: =Q21+U21 -> 3102912.1
C22: Cumulative | V22: =SUM(V4:V21) -> 62101648 | W22: =SUM(W4:W21) -> 3102912.1

Sheet NAV Rollforward
A1: Quarterly NAV Rollforward
A2: Beginning NAV -> Ending NAV bridge, tying to portfolio fair values each quarter
B3: Qtr # | C3: Quarter | D3: Beginning NAV | E3: Contributions | F3: Management Fees | G3: Realized Gain/(Loss) | H3: Unrealized Gain/(Loss) | I3: Distributions | J3: Ending NAV | K3: Ties?
B4: 1 | C4: =Quarters!$E$4 -> Q1 2022 | D4: 0 | E4: ='Capital Call Schedule'!$F$4 -> 6250000 | F4: =-'Mgmt Fee Schedule'!$G$4 -> -250000 | G4: =SUMIFS('Portfolio Marks'!$L:$L,'Portfolio Marks'!$D:$D,B4) -> 0 | H4: =(SUMIFS('Portfolio Marks'!$G:$G,'Portfolio Marks'!$D:$D,B4)-SUMIFS('Portfolio Marks'!$J:$J,'Portfolio Marks'!$D:$D,B4))-D4-E4+'Mgmt Fee Schedule'!$G$4-G4+'Distribution Waterfall'!$D$4 -> 0 | I4: =-'Distribution Waterfall'!$D$4 -> 0 | J4: =D4+E4+F4+G4+H4+I4 -> 6000000 | K4: =IF(ROUND(J4-(SUMIFS('Portfolio Marks'!$G:$G,'Portfolio Marks'!$D:$D,B4)-SUMIFS('Portfolio Marks'!$J:$J,'Portfolio Marks'!$D:$D,B4)),2)=0,"OK","ERROR") -> OK
B5: 2 | C5: =Quarters!$E$5 -> Q2 2022 | D5: =J4 -> 6000000 | E5: ='Capital Call Schedule'!$F$5 -> 5750000 | F5: =-'Mgmt Fee Schedule'!$G$5 -> -250000 | G5: =SUMIFS('Portfolio Marks'!$L:$L,'Portfolio Marks'!$D:$D,B5) -> 0 | H5: =(SUMIFS('Portfolio Marks'!$G:$G,'Portfolio Marks'!$D:$D,B5)-SUMIFS('Portfolio Marks'!$J:$J,'Portfolio Marks'!$D:$D,B5))-D5-E5+'Mgmt Fee Schedule'!$G$5-G5+'Distribution Waterfall'!$D$5 -> 657424.54 | I5: =-'Distribution Waterfall'!$D$5 -> 0 | J5: =D5+E5+F5+G5+H5+I5 -> 12157425 | K5: =IF(ROUND(J5-(SUMIFS('Portfolio Marks'!$G:$G,'Portfolio Marks'!$D:$D,B5)-SUMIFS('Portfolio Marks'!$J:$J,'Portfolio Marks'!$D:$D,B5)),2)=0,"OK","ERROR") -> OK
B6: 3 | C6: =Quarters!$E$6 -> Q3 2022 | D6: =J5 -> 12157425 | E6: ='Capital Call Schedule'!$F$6 -> 4750000 | F6: =-'Mgmt Fee Schedule'!$G$6 -> -250000 | G6: =SUMIFS('Portfolio Marks'!$L:$L,'Portfolio Marks'!$D:$D,B6) -> 0 | H6: =(SUMIFS('Portfolio Marks'!$G:$G,'Portfolio Marks'!$D:$D,B6)-SUMIFS('Portfolio Marks'!$J:$J,'Portfolio Marks'!$D:$D,B6))-D6-E6+'Mgmt Fee Schedule'!$G$6-G6+'Distribution Waterfall'!$D$6 -> 896533.37 | I6: =-'Distribution Waterfall'!$D$6 -> 0 | J6: =D6+E6+F6+G6+H6+I6 -> 17553958 | K6: =IF(ROUND(J6-(SUMIFS('Portfolio Marks'!$G:$G,'Portfolio Marks'!$D:$D,B6)-SUMIFS('Portfolio Marks'!$J:$J,'Portfolio Marks'!$D:$D,B6)),2)=0,"OK","ERROR") -> OK
B7: 4 | C7: =Quarters!$E$7 -> Q4 2022 | D7: =J6 -> 17553958 | E7: ='Capital Call Schedule'!$F$7 -> 5250000 | F7: =-'Mgmt Fee Schedule'!$G$7 -> -250000 | G7: =SUMIFS('Portfolio Marks'!$L:$L,'Portfolio Marks'!$D:$D,B7) -> 0 | H7: =(SUMIFS('Portfolio Marks'!$G:$G,'Portfolio Marks'!$D:$D,B7)-SUMIFS('Portfolio Marks'!$J:$J,'Portfolio Marks'!$D:$D,B7))-D7-E7+'Mgmt Fee Schedule'!$G$7-G7+'Distribution Waterfall'!$D$7 -> 1008642.5 | I7: =-'Distribution Waterfall'!$D$7 -> 0 | J7: =D7+E7+F7+G7+H7+I7 -> 23562600 | K7: =IF(ROUND(J7-(SUMIFS('Portfolio Marks'!$G:$G,'Portfolio Marks'!$D:$D,B7)-SUMIFS('Portfolio Marks'!$J:$J,'Portfolio Marks'!$D:$D,B7)),2)=0,"OK","ERROR") -> OK
B8: 5 | C8: =Quarters!$E$8 -> Q1 2023 | D8: =J7 -> 23562600 | E8: ='Capital Call Schedule'!$F$8 -> 4250000 | F8: =-'Mgmt Fee Schedule'!$G$8 -> -250000 | G8: =SUMIFS('Portfolio Marks'!$L:$L,'Portfolio Marks'!$D:$D,B8) -> 0 | H8: =(SUMIFS('Portfolio Marks'!$G:$G,'Portfolio Marks'!$D:$D,B8)-SUMIFS('Portfolio Marks'!$J:$J,'Portfolio Marks'!$D:$D,B8))-D8-E8+'Mgmt Fee Schedule'!$G$8-G8+'Distribution Waterfall'!$D$8 -> 1485986.9 | I8: =-'Distribution Waterfall'!$D$8 -> 0 | J8: =D8+E8+F8+G8+H8+I8 -> 29048587 | K8: =IF(ROUND(J8-(SUMIFS('Portfolio Marks'!$G:$G,'Portfolio Marks'!$D:$D,B8)-SUMIFS('Portfolio Marks'!$J:$J,'Portfolio Marks'!$D:$D,B8)),2)=0,"OK","ERROR") -> OK
B9: 6 | C9: =Quarters!$E$9 -> Q2 2023 | D9: =J8 -> 29048587 | E9: ='Capital Call Schedule'!$F$9 -> 5250000 | F9: =-'Mgmt Fee Schedule'!$G$9 -> -250000 | G9: =SUMIFS('Portfolio Marks'!$L:$L,'Portfolio Marks'!$D:$D,B9) -> 0 | H9: =(SUMIFS('Portfolio Marks'!$G:$G,'Portfolio Marks'!$D:$D,B9)-SUMIFS('Portfolio Marks'!$J:$J,'Portfolio Marks'!$D:$D,B9))-D9-E9+'Mgmt Fee Schedule'!$G$9-G9+'Distribution Waterfall'!$D$9 -> 1163810.5 | I9: =-'Distribution Waterfall'!$D$9 -> 0 | J9: =D9+E9+F9+G9+H9+I9 -> 35212398 | K9: =IF(ROUND(J9-(SUMIFS('Portfolio Marks'!$G:$G,'Portfolio Marks'!$D:$D,B9)-SUMIFS('Portfolio Marks'!$J:$J,'Portfolio Marks'!$D:$D,B9)),2)=0,"OK","ERROR") -> OK
B10: 7 | C10: =Quarters!$E$10 -> Q3 2023 | D10: =J9 -> 35212398 | E10: ='Capital Call Schedule'!$F$10 -> 4750000 | F10: =-'Mgmt Fee Schedule'!$G$10 -> -250000 | G10: =SUMIFS('Portfolio Marks'!$L:$L,'Portfolio Marks'!$D:$D,B10) -> 0 | H10: =(SUMIFS('Portfolio Marks'!$G:$G,'Portfolio Marks'!$D:$D,B10)-SUMIFS('Portfolio Marks'!$J:$J,'Portfolio Marks'!$D:$D,B10))-D10-E10+'Mgmt Fee Schedule'!$G$10-G10+'Distribution Waterfall'!$D$10 -> 2059134.7 | I10: =-'Distribution Waterfall'!$D$10 -> 0 | J10: =D10+E10+F10+G10+H10+I10 -> 41771532 | K10: =IF(ROUND(J10-(SUMIFS('Portfolio Marks'!$G:$G,'Portfolio Marks'!$D:$D,B10)-SUMIFS('Portfolio Marks'!$J:$J,'Portfolio Marks'!$D:$D,B10)),2)=0,"OK","ERROR") -> OK
B11: 8 | C11: =Quarters!$E$11 -> Q4 2023 | D11: =J10 -> 41771532 | E11: ='Capital Call Schedule'!$F$11 -> 3750000 | F11: =-'Mgmt Fee Schedule'!$G$11 -> -250000 | G11: =SUMIFS('Portfolio Marks'!$L:$L,'Portfolio Marks'!$D:$D,B11) -> 0 | H11: =(SUMIFS('Portfolio Marks'!$G:$G,'Portfolio Marks'!$D:$D,B11)-SUMIFS('Portfolio Marks'!$J:$J,'Portfolio Marks'!$D:$D,B11))-D11-E11+'Mgmt Fee Schedule'!$G$11-G11+'Distribution Waterfall'!$D$11 -> 2512421.3 | I11: =-'Distribution Waterfall'!$D$11 -> 0 | J11: =D11+E11+F11+G11+H11+I11 -> 47783954 | K11: =IF(ROUND(J11-(SUMIFS('Portfolio Marks'!$G:$G,'Portfolio Marks'!$D:$D,B11)-SUMIFS('Portfolio Marks'!$J:$J,'Portfolio Marks'!$D:$D,B11)),2)=0,"OK","ERROR") -> OK
B12: 9 | C12: =Quarters!$E$12 -> Q1 2024 | D12: =J11 -> 47783954 | E12: ='Capital Call Schedule'!$F$12 -> 4250000 | F12: =-'Mgmt Fee Schedule'!$G$12 -> -250000 | G12: =SUMIFS('Portfolio Marks'!$L:$L,'Portfolio Marks'!$D:$D,B12) -> 0 | H12: =(SUMIFS('Portfolio Marks'!$G:$G,'Portfolio Marks'!$D:$D,B12)-SUMIFS('Portfolio Marks'!$J:$J,'Portfolio Marks'!$D:$D,B12))-D12-E12+'Mgmt Fee Schedule'!$G$12-G12+'Distribution Waterfall'!$D$12 -> 2864578.8 | I12: =-'Distribution Waterfall'!$D$12 -> 0 | J12: =D12+E12+F12+G12+H12+I12 -> 54648533 | K12: =IF(ROUND(J12-(SUMIFS('Portfolio Marks'!$G:$G,'Portfolio Marks'!$D:$D,B12)-SUMIFS('Portfolio Marks'!$J:$J,'Portfolio Marks'!$D:$D,B12)),2)=0,"OK","ERROR") -> OK
B13: 10 | C13: =Quarters!$E$13 -> Q2 2024 | D13: =J12 -> 54648533 | E13: ='Capital Call Schedule'!$F$13 -> 3750000 | F13: =-'Mgmt Fee Schedule'!$G$13 -> -250000 | G13: =SUMIFS('Portfolio Marks'!$L:$L,'Portfolio Marks'!$D:$D,B13) -> 0 | H13: =(SUMIFS('Portfolio Marks'!$G:$G,'Portfolio Marks'!$D:$D,B13)-SUMIFS('Portfolio Marks'!$J:$J,'Portfolio Marks'!$D:$D,B13))-D13-E13+'Mgmt Fee Schedule'!$G$13-G13+'Distribution Waterfall'!$D$13 -> 3303626.8 | I13: =-'Distribution Waterfall'!$D$13 -> 0 | J13: =D13+E13+F13+G13+H13+I13 -> 61452159 | K13: =IF(ROUND(J13-(SUMIFS('Portfolio Marks'!$G:$G,'Portfolio Marks'!$D:$D,B13)-SUMIFS('Portfolio Marks'!$J:$J,'Portfolio Marks'!$D:$D,B13)),2)=0,"OK","ERROR") -> OK
B14: 11 | C14: =Quarters!$E$14 -> Q3 2024 | D14: =J13 -> 61452159 | E14: ='Capital Call Schedule'!$F$14 -> 250000 | F14: =-'Mgmt Fee Schedule'!$G$14 -> -250000 | G14: =SUMIFS('Portfolio Marks'!$L:$L,'Portfolio Marks'!$D:$D,B14) -> 0 | H14: =(SUMIFS('Portfolio Marks'!$G:$G,'Portfolio Marks'!$D:$D,B14)-SUMIFS('Portfolio Marks'!$J:$J,'Portfolio Marks'!$D:$D,B14))-D14-E14+'Mgmt Fee Schedule'!$G$14-G14+'Distribution Waterfall'!$D$14 -> 3663717 | I14: =-'Distribution Waterfall'!$D$14 -> 0 | J14: =D14+E14+F14+G14+H14+I14 -> 65115876 | K14: =IF(ROUND(J14-(SUMIFS('Portfolio Marks'!$G:$G,'Portfolio Marks'!$D:$D,B14)-SUMIFS('Portfolio Marks'!$J:$J,'Portfolio Marks'!$D:$D,B14)),2)=0,"OK","ERROR") -> OK
B15: 12 | C15: =Quarters!$E$15 -> Q4 2024 | D15: =J14 -> 65115876 | E15: ='Capital Call Schedule'!$F$15 -> 250000 | F15: =-'Mgmt Fee Schedule'!$G$15 -> -250000 | G15: =SUMIFS('Portfolio Marks'!$L:$L,'Portfolio Marks'!$D:$D,B15) -> 0 | H15: =(SUMIFS('Portfolio Marks'!$G:$G,'Portfolio Marks'!$D:$D,B15)-SUMIFS('Portfolio Marks'!$J:$J,'Portfolio Marks'!$D:$D,B15))-D15-E15+'Mgmt Fee Schedule'!$G$15-G15+'Distribution Waterfall'!$D$15 -> 4363782.8 | I15: =-'Distribution Waterfall'!$D$15 -> 0 | J15: =D15+E15+F15+G15+H15+I15 -> 69479659 | K15: =IF(ROUND(J15-(SUMIFS('Portfolio Marks'!$G:$G,'Portfolio Marks'!$D:$D,B15)-SUMIFS('Portfolio Marks'!$J:$J,'Portfolio Marks'!$D:$D,B15)),2)=0,"OK","ERROR") -> OK
B16: 13 | C16: =Quarters!$E$16 -> Q1 2025 | D16: =J15 -> 69479659 | E16: ='Capital Call Schedule'!$F$16 -> 227500 | F16: =-'Mgmt Fee Schedule'!$G$16 -> -227500 | G16: =SUMIFS('Portfolio Marks'!$L:$L,'Portfolio Marks'!$D:$D,B16) -> 13411887 | H16: =(SUMIFS('Portfolio Marks'!$G:$G,'Portfolio Marks'!$D:$D,B16)-SUMIFS('Portfolio Marks'!$J:$J,'Portfolio Marks'!$D:$D,B16))-D16-E16+'Mgmt Fee Schedule'!$G$16-G16+'Distribution Waterfall'!$D$16 -> -8476207.7 | I16: =-'Distribution Waterfall'!$D$16 -> -19411887 | J16: =D16+E16+F16+G16+H16+I16 -> 55003452 | K16: =IF(ROUND(J16-(SUMIFS('Portfolio Marks'!$G:$G,'Portfolio Marks'!$D:$D,B16)-SUMIFS('Portfolio Marks'!$J:$J,'Portfolio Marks'!$D:$D,B16)),2)=0,"OK","ERROR") -> OK
B17: 14 | C17: =Quarters!$E$17 -> Q2 2025 | D17: =J16 -> 55003452 | E17: ='Capital Call Schedule'!$F$17 -> 227500 | F17: =-'Mgmt Fee Schedule'!$G$17 -> -227500 | G17: =SUMIFS('Portfolio Marks'!$L:$L,'Portfolio Marks'!$D:$D,B17) -> 0 | H17: =(SUMIFS('Portfolio Marks'!$G:$G,'Portfolio Marks'!$D:$D,B17)-SUMIFS('Portfolio Marks'!$J:$J,'Portfolio Marks'!$D:$D,B17))-D17-E17+'Mgmt Fee Schedule'!$G$17-G17+'Distribution Waterfall'!$D$17 -> 2950760.3 | I17: =-'Distribution Waterfall'!$D$17 -> 0 | J17: =D17+E17+F17+G17+H17+I17 -> 57954212 | K17: =IF(ROUND(J17-(SUMIFS('Portfolio Marks'!$G:$G,'Portfolio Marks'!$D:$D,B17)-SUMIFS('Portfolio Marks'!$J:$J,'Portfolio Marks'!$D:$D,B17)),2)=0,"OK","ERROR") -> OK
B18: 15 | C18: =Quarters!$E$18 -> Q3 2025 | D18: =J17 -> 57954212 | E18: ='Capital Call Schedule'!$F$18 -> 197500 | F18: =-'Mgmt Fee Schedule'!$G$18 -> -197500 | G18: =SUMIFS('Portfolio Marks'!$L:$L,'Portfolio Marks'!$D:$D,B18) -> 5493565.5 | H18: =(SUMIFS('Portfolio Marks'!$G:$G,'Portfolio Marks'!$D:$D,B18)-SUMIFS('Portfolio Marks'!$J:$J,'Portfolio Marks'!$D:$D,B18))-D18-E18+'Mgmt Fee Schedule'!$G$18-G18+'Distribution Waterfall'!$D$18 -> -2629954.2 | I18: =-'Distribution Waterfall'!$D$18 -> -10993566 | J18: =D18+E18+F18+G18+H18+I18 -> 49824258 | K18: =IF(ROUND(J18-(SUMIFS('Portfolio Marks'!$G:$G,'Portfolio Marks'!$D:$D,B18)-SUMIFS('Portfolio Marks'!$J:$J,'Portfolio Marks'!$D:$D,B18)),2)=0,"OK","ERROR") -> OK
B19: 16 | C19: =Quarters!$E$19 -> Q4 2025 | D19: =J18 -> 49824258 | E19: ='Capital Call Schedule'!$F$19 -> 197500 | F19: =-'Mgmt Fee Schedule'!$G$19 -> -197500 | G19: =SUMIFS('Portfolio Marks'!$L:$L,'Portfolio Marks'!$D:$D,B19) -> 0 | H19: =(SUMIFS('Portfolio Marks'!$G:$G,'Portfolio Marks'!$D:$D,B19)-SUMIFS('Portfolio Marks'!$J:$J,'Portfolio Marks'!$D:$D,B19))-D19-E19+'Mgmt Fee Schedule'!$G$19-G19+'Distribution Waterfall'!$D$19 -> 2378162.4 | I19: =-'Distribution Waterfall'!$D$19 -> 0 | J19: =D19+E19+F19+G19+H19+I19 -> 52202420 | K19: =IF(ROUND(J19-(SUMIFS('Portfolio Marks'!$G:$G,'Portfolio Marks'!$D:$D,B19)-SUMIFS('Portfolio Marks'!$J:$J,'Portfolio Marks'!$D:$D,B19)),2)=0,"OK","ERROR") -> OK
B20: 17 | C20: =Quarters!$E$20 -> Q1 2026 | D20: =J19 -> 52202420 | E20: ='Capital Call Schedule'!$F$20 -> 170000 | F20: =-'Mgmt Fee Schedule'!$G$20 -> -170000 | G20: =SUMIFS('Portfolio Marks'!$L:$L,'Portfolio Marks'!$D:$D,B20) -> 9803878.7 | H20: =(SUMIFS('Portfolio Marks'!$G:$G,'Portfolio Marks'!$D:$D,B20)-SUMIFS('Portfolio Marks'!$J:$J,'Portfolio Marks'!$D:$D,B20))-D20-E20+'Mgmt Fee Schedule'!$G$20-G20+'Distribution Waterfall'!$D$20 -> -7010181.8 | I20: =-'Distribution Waterfall'!$D$20 -> -14803879 | J20: =D20+E20+F20+G20+H20+I20 -> 40192238 | K20: =IF(ROUND(J20-(SUMIFS('Portfolio Marks'!$G:$G,'Portfolio Marks'!$D:$D,B20)-SUMIFS('Portfolio Marks'!$J:$J,'Portfolio Marks'!$D:$D,B20)),2)=0,"OK","ERROR") -> OK
B21: 18 | C21: =Quarters!$E$21 -> Q2 2026 | D21: =J20 -> 40192238 | E21: ='Capital Call Schedule'!$F$21 -> 170000 | F21: =-'Mgmt Fee Schedule'!$G$21 -> -170000 | G21: =SUMIFS('Portfolio Marks'!$L:$L,'Portfolio Marks'!$D:$D,B21) -> 8495229.2 | H21: =(SUMIFS('Portfolio Marks'!$G:$G,'Portfolio Marks'!$D:$D,B21)-SUMIFS('Portfolio Marks'!$J:$J,'Portfolio Marks'!$D:$D,B21))-D21-E21+'Mgmt Fee Schedule'!$G$21-G21+'Distribution Waterfall'!$D$21 -> -6991460.6 | I21: =-'Distribution Waterfall'!$D$21 -> -19995229 | J21: =D21+E21+F21+G21+H21+I21 -> 21700778 | K21: =IF(ROUND(J21-(SUMIFS('Portfolio Marks'!$G:$G,'Portfolio Marks'!$D:$D,B21)-SUMIFS('Portfolio Marks'!$J:$J,'Portfolio Marks'!$D:$D,B21)),2)=0,"OK","ERROR") -> OK

Sheet LP Capital Calls
A1: LP Capital Calls
A2: Each LP's pro-rata share of every quarterly capital call
B3: Qtr # | C3: Quarter | D3: LP ID | E3: LP Name | F3: Investment Call ($) | G3: Mgmt Fee Call ($) | H3: Total Call ($)
B4: 1 | C4: =Quarters!$E$4 -> Q1 2022 | D4: LP-01 | E4: Northbridge State Pension Fund | F4: ='Capital Call Schedule'!$D$4*'LP Register'!$F$4 -> 960000 | G4: ='Capital Call Schedule'!$E$4*'LP Register'!$F$4 -> 40000 | H4: =F4+G4 -> 1000000
B5: 1 | C5: =Quarters!$E$4 -> Q1 2022 | D5: LP-02 | E5: Meridian University Endowment | F5: ='Capital Call Schedule'!$D$4*'LP Register'!$F$5 -> 720000 | G5: ='Capital Call Schedule'!$E$4*'LP Register'!$F$5 -> 30000 | H5: =F5+G5 -> 750000
B6: 1 | C6: =Quarters!$E$4 -> Q1 2022 | D6: LP-03 | E6: Harborview Insurance Co. | F6: ='Capital Call Schedule'!$D$4*'LP Register'!$F$6 -> 660000 | G6: ='Capital Call Schedule'!$E$4*'LP Register'!$F$6 -> 27500 | H6: =F6+G6 -> 687500
B7: 1 | C7: =Quarters!$E$4 -> Q1 2022 | D7: LP-04 | E7: Cascade Partners Fund of Funds | F7: ='Capital Call Schedule'!$D$4*'LP Register'!$F$7 -> 600000 | G7: ='Capital Call Schedule'!$E$4*'LP Register'!$F$7 -> 25000 | H7: =F7+G7 -> 625000
B8: 1 | C8: =Quarters!$E$4 -> Q1 2022 | D8: LP-05 | E8: Elmwood Family Office | F8: ='Capital Call Schedule'!$D$4*'LP Register'!$F$8 -> 480000 | G8: ='Capital Call Schedule'!$E$4*'LP Register'!$F$8 -> 20000 | H8: =F8+G8 -> 500000
B9: 1 | C9: =Quarters!$E$4 -> Q1 2022 | D9: LP-06 | E9: Tanager Sovereign Partners | F9: ='Capital Call Schedule'!$D$4*'LP Register'!$F$9 -> 480000 | G9: ='Capital Call Schedule'!$E$4*'LP Register'!$F$9 -> 20000 | H9: =F9+G9 -> 500000
B10: 1 | C10: =Quarters!$E$4 -> Q1 2022 | D10: LP-07 | E10: Birchwood College Endowment | F10: ='Capital Call Schedule'!$D$4*'LP Register'!$F$10 -> 360000 | G10: ='Capital Call Schedule'!$E$4*'LP Register'!$F$10 -> 15000 | H10: =F10+G10 -> 375000
B11: 1 | C11: =Quarters!$E$4 -> Q1 2022 | D11: LP-08 | E11: Kestrel Insurance Group | F11: ='Capital Call Schedule'!$D$4*'LP Register'!$F$11 -> 300000 | G11: ='Capital Call Schedule'!$E$4*'LP Register'!$F$11 -> 12500 | H11: =F11+G11 -> 312500
B12: 1 | C12: =Quarters!$E$4 -> Q1 2022 | D12: LP-09 | E12: Wrenfield Family Office | F12: ='Capital Call Schedule'!$D$4*'LP Register'!$F$12 -> 240000 | G12: ='Capital Call Schedule'!$E$4*'LP Register'!$F$12 -> 10000 | H12: =F12+G12 -> 250000
B13: 1 | C13: =Quarters!$E$4 -> Q1 2022 | D13: LP-10 | E13: Alder Street Foundation | F13: ='Capital Call Schedule'!$D$4*'LP Register'!$F$13 -> 240000 | G13: ='Capital Call Schedule'!$E$4*'LP Register'!$F$13 -> 10000 | H13: =F13+G13 -> 250000
B14: 1 | C14: =Quarters!$E$4 -> Q1 2022 | D14: LP-11 | E14: Pinecrest Pension Trust | F14: ='Capital Call Schedule'!$D$4*'LP Register'!$F$14 -> 216000 | G14: ='Capital Call Schedule'!$E$4*'LP Register'!$F$14 -> 9000 | H14: =F14+G14 -> 225000
B15: 1 | C15: =Quarters!$E$4 -> Q1 2022 | D15: LP-12 | E15: Ivywood Capital Partners (FoF) | F15: ='Capital Call Schedule'!$D$4*'LP Register'!$F$15 -> 180000 | G15: ='Capital Call Schedule'!$E$4*'LP Register'!$F$15 -> 7500 | H15: =F15+G15 -> 187500
B16: 1 | C16: =Quarters!$E$4 -> Q1 2022 | D16: LP-13 | E16: Grayling Family Office | F16: ='Capital Call Schedule'!$D$4*'LP Register'!$F$16 -> 180000 | G16: ='Capital Call Schedule'!$E$4*'LP Register'!$F$16 -> 7500 | H16: =F16+G16 -> 187500
B17: 1 | C17: =Quarters!$E$4 -> Q1 2022 | D17: LP-14 | E17: Redstone Family Office | F17: ='Capital Call Schedule'!$D$4*'LP Register'!$F$17 -> 192000 | G17: ='Capital Call Schedule'!$E$4*'LP Register'!$F$17 -> 8000 | H17: =F17+G17 -> 200000
B18: 1 | C18: =Quarters!$E$4 -> Q1 2022 | D18: LP-15 | E18: Sable Foundation | F18: ='Capital Call Schedule'!$D$4*'LP Register'!$F$18 -> 192000 | G18: ='Capital Call Schedule'!$E$4*'LP Register'!$F$18 -> 8000 | H18: =F18+G18 -> 200000
B19: 2 | C19: =Quarters!$E$5 -> Q2 2022 | D19: LP-01 | E19: Northbridge State Pension Fund | F19: ='Capital Call Schedule'!$D$5*'LP Register'!$F$4 -> 880000 | G19: ='Capital Call Schedule'!$E$5*'LP Register'!$F$4 -> 40000 | H19: =F19+G19 -> 920000
B20: 2 | C20: =Quarters!$E$5 -> Q2 2022 | D20: LP-02 | E20: Meridian University Endowment | F20: ='Capital Call Schedule'!$D$5*'LP Register'!$F$5 -> 660000 | G20: ='Capital Call Schedule'!$E$5*'LP Register'!$F$5 -> 30000 | H20: =F20+G20 -> 690000
B21: 2 | C21: =Quarters!$E$5 -> Q2 2022 | D21: LP-03 | E21: Harborview Insurance Co. | F21: ='Capital Call Schedule'!$D$5*'LP Register'!$F$6 -> 605000 | G21: ='Capital Call Schedule'!$E$5*'LP Register'!$F$6 -> 27500 | H21: =F21+G21 -> 632500
B22: 2 | C22: =Quarters!$E$5 -> Q2 2022 | D22: LP-04 | E22: Cascade Partners Fund of Funds | F22: ='Capital Call Schedule'!$D$5*'LP Register'!$F$7 -> 550000 | G22: ='Capital Call Schedule'!$E$5*'LP Register'!$F$7 -> 25000 | H22: =F22+G22 -> 575000
B23: 2 | C23: =Quarters!$E$5 -> Q2 2022 | D23: LP-05 | E23: Elmwood Family Office | F23: ='Capital Call Schedule'!$D$5*'LP Register'!$F$8 -> 440000 | G23: ='Capital Call Schedule'!$E$5*'LP Register'!$F$8 -> 20000 | H23: =F23+G23 -> 460000
B24: 2 | C24: =Quarters!$E$5 -> Q2 2022 | D24: LP-06 | E24: Tanager Sovereign Partners | F24: ='Capital Call Schedule'!$D$5*'LP Register'!$F$9 -> 440000 | G24: ='Capital Call Schedule'!$E$5*'LP Register'!$F$9 -> 20000 | H24: =F24+G24 -> 460000
B25: 2 | C25: =Quarters!$E$5 -> Q2 2022 | D25: LP-07 | E25: Birchwood College Endowment | F25: ='Capital Call Schedule'!$D$5*'LP Register'!$F$10 -> 330000 | G25: ='Capital Call Schedule'!$E$5*'LP Register'!$F$10 -> 15000 | H25: =F25+G25 -> 345000
B26: 2 | C26: =Quarters!$E$5 -> Q2 2022 | D26: LP-08 | E26: Kestrel Insurance Group | F26: ='Capital Call Schedule'!$D$5*'LP Register'!$F$11 -> 275000 | G26: ='Capital Call Schedule'!$E$5*'LP Register'!$F$11 -> 12500 | H26: =F26+G26 -> 287500
B27: 2 | C27: =Quarters!$E$5 -> Q2 2022 | D27: LP-09 | E27: Wrenfield Family Office | F27: ='Capital Call Schedule'!$D$5*'LP Register'!$F$12 -> 220000 | G27: ='Capital Call Schedule'!$E$5*'LP Register'!$F$12 -> 10000 | H27: =F27+G27 -> 230000
B28: 2 | C28: =Quarters!$E$5 -> Q2 2022 | D28: LP-10 | E28: Alder Street Foundation | F28: ='Capital Call Schedule'!$D$5*'LP Register'!$F$13 -> 220000 | G28: ='Capital Call Schedule'!$E$5*'LP Register'!$F$13 -> 10000 | H28: =F28+G28 -> 230000
B29: 2 | C29: =Quarters!$E$5 -> Q2 2022 | D29: LP-11 | E29: Pinecrest Pension Trust | F29: ='Capital Call Schedule'!$D$5*'LP Register'!$F$14 -> 198000 | G29: ='Capital Call Schedule'!$E$5*'LP Register'!$F$14 -> 9000 | H29: =F29+G29 -> 207000
B30: 2 | C30: =Quarters!$E$5 -> Q2 2022 | D30: LP-12 | E30: Ivywood Capital Partners (FoF) | F30: ='Capital Call Schedule'!$D$5*'LP Register'!$F$15 -> 165000 | G30: ='Capital Call Schedule'!$E$5*'LP Register'!$F$15 -> 7500 | H30: =F30+G30 -> 172500
B31: 2 | C31: =Quarters!$E$5 -> Q2 2022 | D31: LP-13 | E31: Grayling Family Office | F31: ='Capital Call Schedule'!$D$5*'LP Register'!$F$16 -> 165000 | G31: ='Capital Call Schedule'!$E$5*'LP Register'!$F$16 -> 7500 | H31: =F31+G31 -> 172500
B32: 2 | C32: =Quarters!$E$5 -> Q2 2022 | D32: LP-14 | E32: Redstone Family Office | F32: ='Capital Call Schedule'!$D$5*'LP Register'!$F$17 -> 176000 | G32: ='Capital Call Schedule'!$E$5*'LP Register'!$F$17 -> 8000 | H32: =F32+G32 -> 184000
B33: 2 | C33: =Quarters!$E$5 -> Q2 2022 | D33: LP-15 | E33: Sable Foundation | F33: ='Capital Call Schedule'!$D$5*'LP Register'!$F$18 -> 176000 | G33: ='Capital Call Schedule'!$E$5*'LP Register'!$F$18 -> 8000 | H33: =F33+G33 -> 184000
B34: 3 | C34: =Quarters!$E$6 -> Q3 2022 | D34: LP-01 | E34: Northbridge State Pension Fund | F34: ='Capital Call Schedule'!$D$6*'LP Register'!$F$4 -> 720000 | G34: ='Capital Call Schedule'!$E$6*'LP Register'!$F$4 -> 40000 | H34: =F34+G34 -> 760000
B35: 3 | C35: =Quarters!$E$6 -> Q3 2022 | D35: LP-02 | E35: Meridian University Endowment | F35: ='Capital Call Schedule'!$D$6*'LP Register'!$F$5 -> 540000 | G35: ='Capital Call Schedule'!$E$6*'LP Register'!$F$5 -> 30000 | H35: =F35+G35 -> 570000
